Workbook

Sheet Decade1
A4: DEPARTEMENTS | B4: LOCALITES | C4: HAUTEURS JOURNALIERES DE PLUIE : 1ère DECADE DE AOUT 2025
C6: 1 | D6: 2 | E6: 3 | F6: 4 | G6: 5 | H6: 6 | I6: 7 | J6: 8 | K6: 9 | L6: 10 | M6: NbJP<0 | N6: NbJP ˃ 20mm | O6: Max | P6: Total
A7: ATLANTIQUE-LITTORAL | B7: Agonkanmey | M7: =COUNTIF(C7:L7,">0") -> 0 | N7: =COUNTIF(C7:L7,">20") -> 0 | O7: =MAX(C7:L7) -> 0 | P7: =SUM(C7:L7) -> 0
B8: Cotonou-Aéro | I8: 1.7 | M8: =COUNTIF(C8:L8,">0") -> 1 | N8: =COUNTIF(C8:L8,">20") -> 0 | O8: =MAX(C8:L8) -> 1.7 | P8: =SUM(C8:L8) -> 1.7
B9: Cotonou C. Central | C9: 0 | D9: 0 | E9: 0 | F9: 0 | G9: 0 | H9: 2.2 | I9: 0 | J9: 0 | K9: 0 | L9: 0 | M9: =COUNTIF(C9:L9,">0") -> 1 | N9: =COUNTIF(C9:L9,">20") -> 0 | O9: =MAX(C9:L9) -> 2.2 | P9: =SUM(C9:L9) -> 2.2
B10: Cotonou-Ville | M10: =COUNTIF(C10:L10,">0") -> 0 | N10: =COUNTIF(C10:L10,">20") -> 0 | O10: =MAX(C10:L10) -> 0 | P10: =SUM(C10:L10) -> 0
B11: Cotonou-Port | M11: =COUNTIF(C11:L11,">0") -> 0 | N11: =COUNTIF(C11:L11,">20") -> 0 | O11: =MAX(C11:L11) -> 0 | P11: =SUM(C11:L11) -> 0
B12: Cotonou-Akpakpa | M12: =COUNTIF(C12:L12,">0") -> 0 | N12: =COUNTIF(C12:L12,">20") -> 0 | O12: =MAX(C12:L12) -> 0 | P12: =SUM(C12:L12) -> 0
B13: Cotonou ste Cécile | C13: 0 | D13: 0 | E13: 0 | F13: 0 | G13: 0 | H13: 0 | I13: 0 | J13: 0 | K13: 0 | L13: 0 | M13: =COUNTIF(C13:L13,">0") -> 0 | N13: =COUNTIF(C13:L13,">20") -> 0 | O13: =MAX(C13:L13) -> 0 | P13: =SUM(C13:L13) -> 0
B14: Akossombo | M14: =COUNTIF(C14:L14,">0") -> 0 | N14: =COUNTIF(C14:L14,">20") -> 0 | O14: =MAX(C14:L14) -> 0 | P14: =SUM(C14:L14) -> 0
B15: Allada | M15: =COUNTIF(C15:L15,">0") -> 0 | N15: =COUNTIF(C15:L15,">20") -> 0 | O15: =MAX(C15:L15) -> 0 | P15: =SUM(C15:L15) -> 0
B16: Niaouli | C16: 0 | D16: 0 | E16: 0 | F16: 0 | G16: 0 | H16: 0 | I16: 0 | J16: 0 | K16: 0 | L16: 0 | M16: =COUNTIF(C16:L16,">0") -> 0 | N16: =COUNTIF(C16:L16,">20") -> 0 | O16: =MAX(C16:L16) -> 0 | P16: =SUM(C16:L16) -> 0
B17: Ouidah nord | C17: 0 | D17: 0 | E17: 0 | F17: 0 | G17: 0 | H17: 0 | I17: 0 | J17: 0 | K17: 0 | L17: 0 | M17: =COUNTIF(C17:L17,">0") -> 0 | N17: =COUNTIF(C17:L17,">20") -> 0 | O17: =MAX(C17:L17) -> 0 | P17: =SUM(C17:L17) -> 0
B18: Ouidah ville | C18: 0 | D18: 0 | E18: 0 | F18: 0 | G18: 0 | H18: 0 | I18: 0 | J18: 0 | K18: 0 | L18: 0 | M18: =COUNTIF(C18:L18,">0") -> 0 | N18: =COUNTIF(C18:L18,">20") -> 0 | O18: =MAX(C18:L18) -> 0 | P18: =SUM(C18:L18) -> 0
B19: Sékou | M19: =COUNTIF(C19:L19,">0") -> 0 | N19: =COUNTIF(C19:L19,">20") -> 0 | O19: =MAX(C19:L19) -> 0 | P19: =SUM(C19:L19) -> 0
B20: Toffo | M20: =COUNTIF(C20:L20,">0") -> 0 | N20: =COUNTIF(C20:L20,">20") -> 0 | O20: =MAX(C20:L20) -> 0 | P20: =SUM(C20:L20) -> 0
B21: Soava Ounmè | C21: 0 | D21: 0 | E21: 0 | F21: 0 | G21: 0 | H21: 0 | I21: 0 | J21: 0 | K21: 0 | L21: 0 | M21: =COUNTIF(C21:L21,">0") -> 0 | N21: =COUNTIF(C21:L21,">20") -> 0 | O21: =MAX(C21:L21) -> 0 | P21: =SUM(C21:L21) -> 0
A28: DEPARTEMENTS | B28: LOCALITES | C28: =C4 -> HAUTEURS JOURNALIERES DE PLUIE : 1ère DECADE DE AOUT 2025
C30: 1 | D30: 2 | E30: 3 | F30: 4 | G30: 5 | H30: 6 | I30: 7 | J30: 8 | K30: 9 | L30: 10 | M30: NbJP | N30: NbJP ˃ 20mm | O30: Max | P30: Total
A31: ATACORA-DONGA | B31: Birni | M31: =COUNTIF(C31:L31,">0") -> 0 | N31: =COUNTIF(C31:L31,">20") -> 0 | O31: =MAX(C31:L31) -> 0 | P31: =SUM(C31:L31) -> 0
B32: Boukoumbé | C32: 7.6 | D32: 24 | G32: 22.5 | H32: 0.4 | J32: 62.8 | M32: =COUNTIF(C32:L32,">0") -> 5 | N32: =COUNTIF(C32:L32,">20") -> 3 | O32: =MAX(C32:L32) -> 62.8 | P32: =SUM(C32:L32) -> 117.3
B33: Dassari | M33: =COUNTIF(C33:L33,">0") -> 0 | N33: =COUNTIF(C33:L33,">20") -> 0 | O33: =MAX(C33:L33) -> 0 | P33: =SUM(C33:L33) -> 0
B34: Kérou | C34: 13 | D34: 3.7 | E34: 7.7 | G34: 11 | I34: 15 | J34: 19.2 | K34: 10 | M34: =COUNTIF(C34:L34,">0") -> 7 | N34: =COUNTIF(C34:L34,">20") -> 0 | O34: =MAX(C34:L34) -> 19.2 | P34: =SUM(C34:L34) -> 79.6
B35: Kouandé | M35: =COUNTIF(C35:L35,">0") -> 0 | N35: =COUNTIF(C35:L35,">20") -> 0 | O35: =MAX(C35:L35) -> 0 | P35: =SUM(C35:L35) -> 0
B36: Matéri | C36: 54.6 | F36: 17.7 | G36: 39.4 | H36: 22.1 | I36: 42.2 | M36: =COUNTIF(C36:L36,">0") -> 5 | N36: =COUNTIF(C36:L36,">20") -> 4 | O36: =MAX(C36:L36) -> 54.6 | P36: =SUM(C36:L36) -> 176
B37: Natitingou | C37: 11 | D37: 122 | E37: 0 | F37: 1 | G37: 20.2 | I37: 6.5 | J37: 19.6 | M37: =COUNTIF(C37:L37,">0") -> 6 | N37: =COUNTIF(C37:L37,">20") -> 2 | O37: =MAX(C37:L37) -> 122 | P37: =SUM(C37:L37) -> 180.3
B38: Porga | M38: =COUNTIF(C38:L38,">0") -> 0 | N38: =COUNTIF(C38:L38,">20") -> 0 | O38: =MAX(C38:L38) -> 0 | P38: =SUM(C38:L38) -> 0
B39: Tanguiéta | M39: =COUNTIF(C39:L39,">0") -> 0 | N39: =COUNTIF(C39:L39,">20") -> 0 | O39: =MAX(C39:L39) -> 0 | P39: =SUM(C39:L39) -> 0
B40: Péhunco | C40: 8.5 | D40: 4.3 | E40: 19.6 | G40: 4.9 | L40: 12.8 | M40: =COUNTIF(C40:L40,">0") -> 5 | N40: =COUNTIF(C40:L40,">20") -> 0 | O40: =MAX(C40:L40) -> 19.6 | P40: =SUM(C40:L40) -> 50.1
B41: Natitingou-ville | M41: =COUNTIF(C41:L41,">0") -> 0 | N41: =COUNTIF(C41:L41,">20") -> 0 | O41: =MAX(C41:L41) -> 0 | P41: =SUM(C41:L41) -> 0
B42: Bassila | C42: 64 | D42: 2 | G42: 7.6 | K42: 16 | M42: =COUNTIF(C42:L42,">0") -> 4 | N42: =COUNTIF(C42:L42,">20") -> 1 | O42: =MAX(C42:L42) -> 64 | P42: =SUM(C42:L42) -> 89.6
B43: Djougou | C43: 21.5 | D43: 11 | F43: 11 | G43: 27.4 | I43: 4.9 | J43: 1.7 | M43: =COUNTIF(C43:L43,">0") -> 6 | N43: =COUNTIF(C43:L43,">20") -> 2 | O43: =MAX(C43:L43) -> 27.4 | P43: =SUM(C43:L43) -> 77.5
B44: Copargo | C44: 7.9 | D44: 20.2 | E44: 6.6 | F44: 5 | G44: 20.7 | I44: 4.8 | J44: T | K44: T | M44: =COUNTIF(C44:L44,">0") -> 6 | N44: =COUNTIF(C44:L44,">20") -> 2 | O44: =MAX(C44:L44) -> 20.7 | P44: =SUM(C44:L44) -> 65.2
B45: Partago | M45: =COUNTIF(C45:L45,">0") -> 0 | N45: =COUNTIF(C45:L45,">20") -> 0 | O45: =MAX(C45:L45) -> 0 | P45: =SUM(C45:L45) -> 0
B46: Pénessoulou | C46: 1.7 | D46: 24.5 | E46: 0.7 | F46: 2.5 | G46: 14.5 | M46: =COUNTIF(C46:L46,">0") -> 5 | N46: =COUNTIF(C46:L46,">20") -> 1 | O46: =MAX(C46:L46) -> 24.5 | P46: =SUM(C46:L46) -> 43.9
B47: Sémèrè | M47: =COUNTIF(C47:L47,">0") -> 0 | N47: =COUNTIF(C47:L47,">20") -> 0 | O47: =MAX(C47:L47) -> 0 | P47: =SUM(C47:L47) -> 0
A52: DEPARTEMENTS | B52: LOCALITES | C52: =C4 -> HAUTEURS JOURNALIERES DE PLUIE : 1ère DECADE DE AOUT 2025
C54: 1 | D54: 2 | E54: 3 | F54: 4 | G54: 5 | H54: 6 | I54: 7 | J54: 8 | K54: 9 | L54: 10 | M54: NbJP | N54: NbJP ˃ 20mm | O54: Max | P54: Total
A55: BORGOU-ALIBORI | B55: Alfakoara | C55: 0 | D55: 0 | E55: 0 | F55: 0 | G55: 0 | H55: 0 | I55: 0 | J55: 0 | K55: 0 | L55: 0 | M55: =COUNTIF(C55:L55,">0") -> 0 | N55: =COUNTIF(C55:L55,">20") -> 0 | O55: =MAX(C55:L55) -> 0 | P55: =SUM(C55:L55) -> 0
B56: Banikoara | C56: 0 | D56: 22.1 | E56: 32.3 | F56: 0 | G56: 0 | H56: 14.8 | I56: 0 | J56: 0 | K56: 49.8 | L56: 0 | M56: =COUNTIF(C56:L56,">0") -> 4 | N56: =COUNTIF(C56:L56,">20") -> 3 | O56: =MAX(C56:L56) -> 49.8 | P56: =SUM(C56:L56) -> 119
...

Sheet Decade2
A2: DEPARTEMENTS | B2: LOCALITES | C2: HAUTEURS JOURNALIERES DE PLUIE : 2ème DECADE DU MOIS DE AOUT 2025
C4: 11 | D4: 12 | E4: 13 | F4: 14 | G4: 15 | H4: 16 | I4: 17 | J4: 18 | K4: 19 | L4: 20 | M4: NbJP>0 | N4: NbJP ˃ 20mm | O4: Max | P4: Total
A5: ATLANTIQUE-LITTORAL | B5: Agonkanmey | M5: =COUNTIF(C5:L5,">0") -> 0 | N5: =COUNTIF(C5:L5,">20") -> 0 | O5: =MAX(C5:L5) -> 0 | P5: =SUM(C5:L5) -> 0
B6: Cotonou-Aéro | M6: =COUNTIF(C6:L6,">0") -> 0 | N6: =COUNTIF(C6:L6,">20") -> 0 | O6: =MAX(C6:L6) -> 0 | P6: =SUM(C6:L6) -> 0
B7: Cotonou C. Central | M7: =COUNTIF(C7:L7,">0") -> 0 | N7: =COUNTIF(C7:L7,">20") -> 0 | O7: =MAX(C7:L7) -> 0 | P7: =SUM(C7:L7) -> 0
B8: Cotonou-Ville | M8: =COUNTIF(C8:L8,">0") -> 0 | N8: =COUNTIF(C8:L8,">20") -> 0 | O8: =MAX(C8:L8) -> 0 | P8: =SUM(C8:L8) -> 0
B9: Cotonou-Port | M9: =COUNTIF(C9:L9,">0") -> 0 | N9: =COUNTIF(C9:L9,">20") -> 0 | O9: =MAX(C9:L9) -> 0 | P9: =SUM(C9:L9) -> 0
B10: Cotonou-Akpakpa | M10: =COUNTIF(C10:L10,">0") -> 0 | N10: =COUNTIF(C10:L10,">20") -> 0 | O10: =MAX(C10:L10) -> 0 | P10: =SUM(C10:L10) -> 0
B11: Cotonou ste Cécile | M11: =COUNTIF(C11:L11,">0") -> 0 | N11: =COUNTIF(C11:L11,">20") -> 0 | O11: =MAX(C11:L11) -> 0 | P11: =SUM(C11:L11) -> 0
B12: Akossombo | M12: =COUNTIF(C12:L12,">0") -> 0 | N12: =COUNTIF(C12:L12,">20") -> 0 | O12: =MAX(C12:L12) -> 0 | P12: =SUM(C12:L12) -> 0
B13: Allada | M13: =COUNTIF(C13:L13,">0") -> 0 | N13: =COUNTIF(C13:L13,">20") -> 0 | O13: =MAX(C13:L13) -> 0 | P13: =SUM(C13:L13) -> 0
B14: Niaouli | M14: =COUNTIF(C14:L14,">0") -> 0 | N14: =COUNTIF(C14:L14,">20") -> 0 | O14: =MAX(C14:L14) -> 0 | P14: =SUM(C14:L14) -> 0
B15: Ouidah nord | I15: 0.3 | M15: =COUNTIF(C15:L15,">0") -> 1 | N15: =COUNTIF(C15:L15,">20") -> 0 | O15: =MAX(C15:L15) -> 0.3 | P15: =SUM(C15:L15) -> 0.3
B16: Ouidah ville | M16: =COUNTIF(C16:L16,">0") -> 0 | N16: =COUNTIF(C16:L16,">20") -> 0 | O16: =MAX(C16:L16) -> 0 | P16: =SUM(C16:L16) -> 0
B17: Sékou | M17: =COUNTIF(C17:L17,">0") -> 0 | N17: =COUNTIF(C17:L17,">20") -> 0 | O17: =MAX(C17:L17) -> 0 | P17: =SUM(C17:L17) -> 0
B18: Toffo | M18: =COUNTIF(C18:L18,">0") -> 0 | N18: =COUNTIF(C18:L18,">20") -> 0 | O18: =MAX(C18:L18) -> 0 | P18: =SUM(C18:L18) -> 0
B19: Soava Ounmè | M19: =COUNTIF(C19:L19,">0") -> 0 | N19: =COUNTIF(C19:L19,">20") -> 0 | O19: =MAX(C19:L19) -> 0 | P19: =SUM(C19:L19) -> 0
A22: DEPARTEMENTS | B22: LOCALITES | C22: =C2 -> HAUTEURS JOURNALIERES DE PLUIE : 2ème DECADE DU MOIS DE AOUT 2025
C24: 11 | D24: 12 | E24: 13 | F24: 14 | G24: 15 | H24: 16 | I24: 17 | J24: 18 | K24: 19 | L24: 20 | M24: NbJP | N24: NbJP ˃ 20mm | O24: Max | P24: Total
A25: ATACORA-DONGA | B25: Birni | D25: 22 | E25: 8 | G25: 16 | J25: 31 | K25: 5 | L25: 22 | M25: =COUNTIF(C25:L25,">0") -> 6 | N25: =COUNTIF(C25:L25,">20") -> 3 | O25: =MAX(C25:L25) -> 31 | P25: =SUM(C25:L25) -> 104
B26: Boukoumbé | C26: 14.4 | E26: 32.8 | F26: 10.2 | J26: 23.1 | M26: =COUNTIF(C26:L26,">0") -> 4 | N26: =COUNTIF(C26:L26,">20") -> 2 | O26: =MAX(C26:L26) -> 32.8 | P26: =SUM(C26:L26) -> 80.5
B27: Dassari | C27: 22.6 | E27: 19.1 | G27: 70.1 | H27: 10.3 | I27: 9.6 | J27: 18.7 | K27: 0.4 | M27: =COUNTIF(C27:L27,">0") -> 7 | N27: =COUNTIF(C27:L27,">20") -> 2 | O27: =MAX(C27:L27) -> 70.1 | P27: =SUM(C27:L27) -> 150.8
B28: Kérou | C28: 52.2 | E28: 10.2 | F28: 57.8 | H28: 21.7 | I28: 24.3 | M28: =COUNTIF(C28:L28,">0") -> 5 | N28: =COUNTIF(C28:L28,">20") -> 4 | O28: =MAX(C28:L28) -> 57.8 | P28: =SUM(C28:L28) -> 166.2
B29: Kouandé | C29: 13.2 | F29: 1.4 | G29: 65 | H29: 11.3 | I29: 7.2 | J29: 24.6 | M29: =COUNTIF(C29:L29,">0") -> 6 | N29: =COUNTIF(C29:L29,">20") -> 2 | O29: =MAX(C29:L29) -> 65 | P29: =SUM(C29:L29) -> 122.7
B30: Matéri | C30: 17.2 | H30: 68.9 | J30: 18.2 | M30: =COUNTIF(C30:L30,">0") -> 3 | N30: =COUNTIF(C30:L30,">20") -> 1 | O30: =MAX(C30:L30) -> 68.9 | P30: =SUM(C30:L30) -> 104.3
B31: Natitingou | C31: 32.1 | E31: 1 | F31: 25.2 | G31: 6.6 | H31: 15.5 | J31: 43.1 | K31: 0.6 | M31: =COUNTIF(C31:L31,">0") -> 7 | N31: =COUNTIF(C31:L31,">20") -> 3 | O31: =MAX(C31:L31) -> 43.1 | P31: =SUM(C31:L31) -> 124.1
B32: Porga | M32: =COUNTIF(C32:L32,">0") -> 0 | N32: =COUNTIF(C32:L32,">20") -> 0 | O32: =MAX(C32:L32) -> 0 | P32: =SUM(C32:L32) -> 0
B33: Tanguiéta | M33: =COUNTIF(C33:L33,">0") -> 0 | N33: =COUNTIF(C33:L33,">20") -> 0 | O33: =MAX(C33:L33) -> 0 | P33: =SUM(C33:L33) -> 0
B34: Péhunco | C34: 90.9 | G34: 22.1 | H34: 12.3 | M34: =COUNTIF(C34:L34,">0") -> 3 | N34: =COUNTIF(C34:L34,">20") -> 2 | O34: =MAX(C34:L34) -> 90.9 | P34: =SUM(C34:L34) -> 125.3
B35: Natitingou-ville | M35: =COUNTIF(C35:L35,">0") -> 0 | N35: =COUNTIF(C35:L35,">20") -> 0 | O35: =MAX(C35:L35) -> 0 | P35: =SUM(C35:L35) -> 0
B36: Bassila | G36: 3.7 | K36: 2.4 | M36: =COUNTIF(C36:L36,">0") -> 2 | N36: =COUNTIF(C36:L36,">20") -> 0 | O36: =MAX(C36:L36) -> 3.7 | P36: =SUM(C36:L36) -> 6.1
B37: Djougou | M37: =COUNTIF(C37:L37,">0") -> 0 | N37: =COUNTIF(C37:L37,">20") -> 0 | O37: =MAX(C37:L37) -> 0 | P37: =SUM(C37:L37) -> 0
B38: Copargo | C38: 28.2 | D38: 25.2 | G38: 6.3 | H38: 5.3 | I38: 24 | J38: 44.7 | M38: =COUNTIF(C38:L38,">0") -> 6 | N38: =COUNTIF(C38:L38,">20") -> 4 | O38: =MAX(C38:L38) -> 44.7 | P38: =SUM(C38:L38) -> 133.7
B39: Partago | C39: 11.9 | E39: 28.3 | G39: 27.3 | J39: 63.7 | M39: =COUNTIF(C39:L39,">0") -> 4 | N39: =COUNTIF(C39:L39,">20") -> 3 | O39: =MAX(C39:L39) -> 63.7 | P39: =SUM(C39:L39) -> 131.2
B40: onklou | C40: 26.1 | D40: 65.4 | G40: 69.6 | J40: 44.3 | M40: =COUNTIF(C40:L40,">0") -> 4 | N40: =COUNTIF(C40:L40,">20") -> 4 | O40: =MAX(C40:L40) -> 69.6 | P40: =SUM(C40:L40) -> 205.4
B41: Pénessoulou | D41: 3.5 | F41: 9.5 | G41: 10.5 | H41: 15.5 | K41: 56.5 | M41: =COUNTIF(C41:L41,">0") -> 5 | N41: =COUNTIF(C41:L41,">20") -> 1 | O41: =MAX(C41:L41) -> 56.5 | P41: =SUM(C41:L41) -> 95.5
B42: Sémèrè | M42: =COUNTIF(C42:L42,">0") -> 0 | N42: =COUNTIF(C42:L42,">20") -> 0 | O42: =MAX(C42:L42) -> 0 | P42: =SUM(C42:L42) -> 0
A45: DEPARTEMENTS | B45: LOCALITES | C45: =C2 -> HAUTEURS JOURNALIERES DE PLUIE : 2ème DECADE DU MOIS DE AOUT 2025
C47: 11 | D47: 12 | E47: 13 | F47: 14 | G47: 15 | H47: 16 | I47: 17 | J47: 18 | K47: 19 | L47: 20 | M47: NbJP | N47: NbJP ˃ 20mm | O47: Max | P47: Total
A48: BORGOU-ALIBORI | B48: Alfakoara | M48: =COUNTIF(C48:L48,">0") -> 0 | N48: =COUNTIF(C48:L48,">20") -> 0 | O48: =MAX(C48:L48) -> 0 | P48: =SUM(C48:L48) -> 0
...

Sheet Decade3
A3: DEPARTEMENTS | B3: LOCALITES | C3: HAUTEURS JOURNALIERES DE PLUIE : 3ème DECADE DU MOIS DE AOUT 2025
C5: 21 | D5: 22 | E5: 23 | F5: 24 | G5: 25 | H5: 26 | I5: 27 | J5: 28 | K5: 29 | L5: 30 | M5: 31 | N5: NbJP>0 | O5: NbJP ˃ 20mm | P5: Max | Q5: Total
A6: ATLANTIQUE-LITTORAL | B6: Agonkanmey | N6: =COUNTIF(C6:M6,">0") -> 0 | O6: =COUNTIF(C6:M6,">20") -> 0 | P6: =MAX(C6:M6) -> 0 | Q6: =SUM(C6:M6) -> 0
B7: Cotonou-Aéro | C7: 0.4 | D7: 0 | E7: 0 | F7: 0 | G7: 0 | H7: 0 | I7: 0 | J7: 0 | K7: 0 | L7: 0.4 | M7: 0 | N7: =COUNTIF(C7:M7,">0") -> 2 | O7: =COUNTIF(C7:M7,">20") -> 0 | P7: =MAX(C7:M7) -> 0.4 | Q7: =SUM(C7:M7) -> 0.8
B8: Cotonou C. Central | N8: =COUNTIF(C8:M8,">0") -> 0 | O8: =COUNTIF(C8:M8,">20") -> 0 | P8: =MAX(C8:M8) -> 0 | Q8: =SUM(C8:M8) -> 0
B9: Cotonou-Ville | N9: =COUNTIF(C9:M9,">0") -> 0 | O9: =COUNTIF(C9:M9,">20") -> 0 | P9: =MAX(C9:M9) -> 0 | Q9: =SUM(C9:M9) -> 0
B10: Cotonou-Port | N10: =COUNTIF(C10:M10,">0") -> 0 | O10: =COUNTIF(C10:M10,">20") -> 0 | P10: =MAX(C10:M10) -> 0 | Q10: =SUM(C10:M10) -> 0
B11: Cotonou-Akpakpa | N11: =COUNTIF(C11:M11,">0") -> 0 | O11: =COUNTIF(C11:M11,">20") -> 0 | P11: =MAX(C11:M11) -> 0 | Q11: =SUM(C11:M11) -> 0
B12: Cotonou ste Cécile | N12: =COUNTIF(C12:M12,">0") -> 0 | O12: =COUNTIF(C12:M12,">20") -> 0 | P12: =MAX(C12:M12) -> 0 | Q12: =SUM(C12:M12) -> 0
B13: Akossombo | N13: =COUNTIF(C13:M13,">0") -> 0 | O13: =COUNTIF(C13:M13,">20") -> 0 | P13: =MAX(C13:M13) -> 0 | Q13: =SUM(C13:M13) -> 0
B14: Allada | N14: =COUNTIF(C14:M14,">0") -> 0 | O14: =COUNTIF(C14:M14,">20") -> 0 | P14: =MAX(C14:M14) -> 0 | Q14: =SUM(C14:M14) -> 0
B15: Niaouli | N15: =COUNTIF(C15:M15,">0") -> 0 | O15: =COUNTIF(C15:M15,">20") -> 0 | P15: =MAX(C15:M15) -> 0 | Q15: =SUM(C15:M15) -> 0
B16: Ouidah nord | C16: 0 | D16: 0 | E16: 0 | F16: 0 | G16: 0 | H16: 0 | I16: 0 | J16: 0 | K16: 0.6 | L16: 0.3 | M16: 0 | N16: =COUNTIF(C16:M16,">0") -> 2 | O16: =COUNTIF(C16:M16,">20") -> 0 | P16: =MAX(C16:M16) -> 0.6 | Q16: =SUM(C16:M16) -> 0.9
B17: Ouidah ville | N17: =COUNTIF(C17:M17,">0") -> 0 | O17: =COUNTIF(C17:M17,">20") -> 0 | P17: =MAX(C17:M17) -> 0 | Q17: =SUM(C17:M17) -> 0
B18: Sékou | N18: =COUNTIF(C18:M18,">0") -> 0 | O18: =COUNTIF(C18:M18,">20") -> 0 | P18: =MAX(C18:M18) -> 0 | Q18: =SUM(C18:M18) -> 0
B19: Toffo | N19: =COUNTIF(C19:M19,">0") -> 0 | O19: =COUNTIF(C19:M19,">20") -> 0 | P19: =MAX(C19:M19) -> 0 | Q19: =SUM(C19:M19) -> 0
B20: Soava Ounmè | N20: =COUNTIF(C20:M20,">0") -> 0 | O20: =COUNTIF(C20:M20,">20") -> 0 | P20: =MAX(C20:M20) -> 0 | Q20: =SUM(C20:M20) -> 0
A23: DEPARTEMENTS | B23: LOCALITES | C23: =C3 -> HAUTEURS JOURNALIERES DE PLUIE : 3ème DECADE DU MOIS DE AOUT 2025
C25: 21 | D25: 22 | E25: 23 | F25: 24 | G25: 25 | H25: 26 | I25: 27 | J25: 28 | K25: 29 | L25: 30 | M25: 31 | N25: NbJP | O25: NbJP ˃ 20mm | P25: Max | Q25: Total
A26: ATACORA-DONGA | B26: Birni | N26: =COUNTIF(C26:M26,">0") -> 0 | O26: =COUNTIF(C26:M26,">20") -> 0 | P26: =MAX(C26:M26) -> 0 | Q26: =SUM(C26:M26) -> 0
B27: Boukoumbé | N27: =COUNTIF(C27:M27,">0") -> 0 | O27: =COUNTIF(C27:M27,">20") -> 0 | P27: =MAX(C27:M27) -> 0 | Q27: =SUM(C27:M27) -> 0
B28: Dassari | C28: 17.4 | D28: 21.2 | E28: 0 | F28: 0 | G28: 0 | H28: 25.8 | I28: 0 | J28: 7.7 | K28: 0 | L28: 0 | M28: 0 | N28: =COUNTIF(C28:M28,">0") -> 4 | O28: =COUNTIF(C28:M28,">20") -> 2 | P28: =MAX(C28:M28) -> 25.8 | Q28: =SUM(C28:M28) -> 72.1
B29: Kérou | C29: 0 | D29: 8.7 | E29: 0 | F29: 0 | G29: 2.8 | H29: 14 | I29: 41 | J29: 0 | K29: 6.8 | L29: 7.2 | M29: 0 | N29: =COUNTIF(C29:M29,">0") -> 6 | O29: =COUNTIF(C29:M29,">20") -> 1 | P29: =MAX(C29:M29) -> 41 | Q29: =SUM(C29:M29) -> 80.5
B30: Kouandé | C30: 42.2 | D30: 14.8 | E30: 0 | F30: 0 | G30: 4.3 | H30: 4.8 | I30: 0 | J30: 32.3 | K30: 3.1 | L30: 13.8 | M30: 0 | N30: =COUNTIF(C30:M30,">0") -> 7 | O30: =COUNTIF(C30:M30,">20") -> 2 | P30: =MAX(C30:M30) -> 42.2 | Q30: =SUM(C30:M30) -> 115.3
B31: Matéri | C31: 0 | D31: 0 | E31: 17.6 | F31: 0 | G31: 0 | H31: 0 | I31: 43.1 | J31: 0 | K31: 0 | L31: 47.7 | M31: 0 | N31: =COUNTIF(C31:M31,">0") -> 3 | O31: =COUNTIF(C31:M31,">20") -> 2 | P31: =MAX(C31:M31) -> 47.7 | Q31: =SUM(C31:M31) -> 108.4
B32: Natitingou | C32: 12.9 | D32: 15.8 | E32: 0 | F32: 0 | G32: 17.1 | H32: 1.8 | I32: 0 | J32: 0 | K32: 19 | L32: 0 | M32: 0 | N32: =COUNTIF(C32:M32,">0") -> 5 | O32: =COUNTIF(C32:M32,">20") -> 0 | P32: =MAX(C32:M32) -> 19 | Q32: =SUM(C32:M32) -> 66.6
B33: Porga | N33: =COUNTIF(C33:M33,">0") -> 0 | O33: =COUNTIF(C33:M33,">20") -> 0 | P33: =MAX(C33:M33) -> 0 | Q33: =SUM(C33:M33) -> 0
B34: Tanguiéta | C34: 2.3 | D34: 10.3 | E34: 0 | F34: 0 | G34: 1.4 | H34: 4.9 | I34: 0 | J34: 0 | K34: 8.2 | L34: 1.9 | M34: 0 | N34: =COUNTIF(C34:M34,">0") -> 6 | O34: =COUNTIF(C34:M34,">20") -> 0 | P34: =MAX(C34:M34) -> 10.3 | Q34: =SUM(C34:M34) -> 29
B35: Péhunco | N35: =COUNTIF(C35:M35,">0") -> 0 | O35: =COUNTIF(C35:M35,">20") -> 0 | P35: =MAX(C35:M35) -> 0 | Q35: =SUM(C35:M35) -> 0
B36: Natitingou-ville | C36: 20.3 | D36: 16.8 | E36: 0 | F36: 0 | G36: 0 | H36: 11.1 | I36: 0 | J36: 0 | K36: 18.9 | L36: 0 | M36: 0.8 | N36: =COUNTIF(C36:M36,">0") -> 5 | O36: =COUNTIF(C36:M36,">20") -> 1 | P36: =MAX(C36:M36) -> 20.3 | Q36: =SUM(C36:M36) -> 67.9
B37: Bassila | C37: 0 | D37: 0 | E37: 24.6 | F37: 0 | G37: 29.2 | H37: 0 | I37: 28.7 | J37: 0 | K37: 0 | L37: 0 | M37: 0 | N37: =COUNTIF(C37:M37,">0") -> 3 | O37: =COUNTIF(C37:M37,">20") -> 3 | P37: =MAX(C37:M37) -> 29.2 | Q37: =SUM(C37:M37) -> 82.5
B38: Djougou | C38: 4.7 | D38: 30.7 | E38: 0 | F38: 0 | G38: 15.9 | H38: 21.1 | I38: 13.2 | J38: 0 | K38: 0 | L38: 0 | M38: 14.9 | N38: =COUNTIF(C38:M38,">0") -> 6 | O38: =COUNTIF(C38:M38,">20") -> 2 | P38: =MAX(C38:M38) -> 30.7 | Q38: =SUM(C38:M38) -> 100.5
B39: Copargo | C39: 32.8 | D39: 14.9 | E39: 0 | F39: 0 | G39: 13.2 | H39: 36.9 | I39: 0 | J39: 0 | K39: 28.5 | L39: 10.2 | M39: 41.3 | N39: =COUNTIF(C39:M39,">0") -> 7 | O39: =COUNTIF(C39:M39,">20") -> 4 | P39: =MAX(C39:M39) -> 41.3 | Q39: =SUM(C39:M39) -> 177.8
B40: Partago | N40: =COUNTIF(C40:M40,">0") -> 0 | O40: =COUNTIF(C40:M40,">20") -> 0 | P40: =MAX(C40:M40) -> 0 | Q40: =SUM(C40:M40) -> 0
B41: Pénessoulou | N41: =COUNTIF(C41:M41,">0") -> 0 | O41: =COUNTIF(C41:M41,">20") -> 0 | P41: =MAX(C41:M41) -> 0 | Q41: =SUM(C41:M41) -> 0
B42: Sémèrè | N42: =COUNTIF(C42:M42,">0") -> 0 | O42: =COUNTIF(C42:M42,">20") -> 0 | P42: =MAX(C42:M42) -> 0 | Q42: =SUM(C42:M42) -> 0
A45: DEPARTEMENTS | B45: LOCALITES | C45: =C3 -> HAUTEURS JOURNALIERES DE PLUIE : 3ème DECADE DU MOIS DE AOUT 2025
C47: 21 | D47: 22 | E47: 23 | F47: 24 | G47: 25 | H47: 26 | I47: 27 | J47: 28 | K47: 29 | L47: 30 | M47: 31 | N47: NbJP | O47: NbJP ˃ 20mm | P47: Max | Q47: Total
A48: BORGOU-ALIBORI | B48: Alfakoara | N48: =COUNTIF(C48:M48,">0") -> 0 | O48: =COUNTIF(C48:M48,">20") -> 0 | P48: =MAX(C48:M48) -> 0 | Q48: =SUM(C48:M48) -> 0
B49: Banikoara | N49: =COUNTIF(C49:M49,">0") -> 0 | O49: =COUNTIF(C49:M49,">20") -> 0 | P49: =MAX(C49:M49) -> 0 | Q49: =SUM(C49:M49) -> 0
...

Sheet Cumul
B2: REPUBLIQUE DU BENIN
B3: MINISTERE DES TRAVAUX PUBLICS ET DES TRANSPORTS
B4: DIRECTION NATIONALE DE LA METEOROLOGIE
B5: DEPARTEMENTS | C5: LOCALITES | D5: CUMUL PLUVIOMETRIQUE MENSUEL: AOUT 2024
D6: 1ère décade | H6: 2ème décade | L6: 3ème décade | P6: Total
D7: NbJP | E7: NbJP > 20 mm | F7: Max | G7: Total (mm) | H7: NbJP | I7: NbJP > 20 mm | J7: Max | K7: Total (mm) | L7: NbJP | M7: NbJP > 20 mm | N7: Max | O7: Total (mm) | P7: NbJP | Q7: NbJP > 20 mm | R7: Max | S7: Total (mm)
B8: ATLANTIQUE-LITTORAL | C8: Agonkanmey | D8: =Decade1!M7 -> 0 | E8: =Decade1!N7 -> 0 | F8: =Decade1!O7 -> 0 | G8: =Decade1!P7 -> 0 | H8: =Decade2!M5 -> 0 | I8: =Decade2!N5 -> 0 | J8: =Decade2!O5 -> 0 | K8: =Decade2!P5 -> 0 | L8: =Decade3!N6 -> 0 | M8: =Decade3!O6 -> 0 | N8: =Decade3!P6 -> 0 | O8: =Decade3!Q6 -> 0 | P8: =SUM(D8,H8,L8) -> 0 | Q8: =SUM(E8,I8,M8) -> 0 | R8: =MAX(F8,J8,N8) -> 0 | S8: =SUM(G8,K8,O8) -> 0
C9: Cotonou-Aero | D9: =Decade1!M8 -> 1 | E9: =Decade1!N8 -> 0 | F9: =Decade1!O8 -> 1.7 | G9: =Decade1!P8 -> 1.7 | H9: =Decade2!M6 -> 0 | I9: =Decade2!N6 -> 0 | J9: =Decade2!O6 -> 0 | K9: =Decade2!P6 -> 0 | L9: =Decade3!N7 -> 2 | M9: =Decade3!O7 -> 0 | N9: =Decade3!P7 -> 0.4 | O9: =Decade3!Q7 -> 0.8 | P9: =SUM(D9,H9,L9) -> 3 | Q9: =SUM(E9,I9,M9) -> 0 | R9: =MAX(F9,J9,N9) -> 1.7 | S9: =SUM(G9,K9,O9) -> 2.5
C10: Cotonou-Commis. | D10: =Decade1!M9 -> 1 | E10: =Decade1!N9 -> 0 | F10: =Decade1!O9 -> 2.2 | G10: =Decade1!P9 -> 2.2 | H10: =Decade2!M7 -> 0 | I10: =Decade2!N7 -> 0 | J10: =Decade2!O7 -> 0 | K10: =Decade2!P7 -> 0 | L10: =Decade3!N8 -> 0 | M10: =Decade3!O8 -> 0 | N10: =Decade3!P8 -> 0 | O10: =Decade3!Q8 -> 0 | P10: =SUM(D10,H10,L10) -> 1 | Q10: =SUM(E10,I10,M10) -> 0 | R10: =MAX(F10,J10,N10) -> 2.2 | S10: =SUM(G10,K10,O10) -> 2.2
C11: Cotonou-Ville | D11: =Decade1!M10 -> 0 | E11: =Decade1!N10 -> 0 | F11: =Decade1!O10 -> 0 | G11: =Decade1!P10 -> 0 | H11: =Decade2!M8 -> 0 | I11: =Decade2!N8 -> 0 | J11: =Decade2!O8 -> 0 | K11: =Decade2!P8 -> 0 | L11: =Decade3!N9 -> 0 | M11: =Decade3!O9 -> 0 | N11: =Decade3!P9 -> 0 | O11: =Decade3!Q9 -> 0 | P11: =SUM(D11,H11,L11) -> 0 | Q11: =SUM(E11,I11,M11) -> 0 | R11: =MAX(F11,J11,N11) -> 0 | S11: =SUM(G11,K11,O11) -> 0
C12: Cotonou-Port | D12: =Decade1!M11 -> 0 | E12: =Decade1!N11 -> 0 | F12: =Decade1!O11 -> 0 | G12: =Decade1!P11 -> 0 | H12: =Decade2!M9 -> 0 | I12: =Decade2!N9 -> 0 | J12: =Decade2!O9 -> 0 | K12: =Decade2!P9 -> 0 | L12: =Decade3!N10 -> 0 | M12: =Decade3!O10 -> 0 | N12: =Decade3!P10 -> 0 | O12: =Decade3!Q10 -> 0 | P12: =SUM(D12,H12,L12) -> 0 | Q12: =SUM(E12,I12,M12) -> 0 | R12: =MAX(F12,J12,N12) -> 0 | S12: =SUM(G12,K12,O12) -> 0
C13: Cotonou-Akpakpa | D13: =Decade1!M12 -> 0 | E13: =Decade1!N12 -> 0 | F13: =Decade1!O12 -> 0 | G13: =Decade1!P12 -> 0 | H13: =Decade2!M10 -> 0 | I13: =Decade2!N10 -> 0 | J13: =Decade2!O10 -> 0 | K13: =Decade2!P10 -> 0 | L13: =Decade3!N11 -> 0 | M13: =Decade3!O11 -> 0 | N13: =Decade3!P11 -> 0 | O13: =Decade3!Q11 -> 0 | P13: =SUM(D13,H13,L13) -> 0 | Q13: =SUM(E13,I13,M13) -> 0 | R13: =MAX(F13,J13,N13) -> 0 | S13: =SUM(G13,K13,O13) -> 0
C14: Cotonou Ste Cécile | D14: =Decade1!M13 -> 0 | E14: =Decade1!N13 -> 0 | F14: =Decade1!O13 -> 0 | G14: =Decade1!P13 -> 0 | H14: =Decade2!M11 -> 0 | I14: =Decade2!N11 -> 0 | J14: =Decade2!O11 -> 0 | K14: =Decade2!P11 -> 0 | L14: =Decade3!N12 -> 0 | M14: =Decade3!O12 -> 0 | N14: =Decade3!P12 -> 0 | O14: =Decade3!Q12 -> 0 | P14: =SUM(D14,H14,L14) -> 0 | Q14: =SUM(E14,I14,M14) -> 0 | R14: =MAX(F14,J14,N14) -> 0 | S14: =SUM(G14,K14,O14) -> 0
C15: Akossombo | D15: =Decade1!M14 -> 0 | E15: =Decade1!N14 -> 0 | F15: =Decade1!O14 -> 0 | G15: =Decade1!P14 -> 0 | H15: =Decade2!M12 -> 0 | I15: =Decade2!N12 -> 0 | J15: =Decade2!O12 -> 0 | K15: =Decade2!P12 -> 0 | L15: =Decade3!N13 -> 0 | M15: =Decade3!O13 -> 0 | N15: =Decade3!P13 -> 0 | O15: =Decade3!Q13 -> 0 | P15: =SUM(D15,H15,L15) -> 0 | Q15: =SUM(E15,I15,M15) -> 0 | R15: =MAX(F15,J15,N15) -> 0 | S15: =SUM(G15,K15,O15) -> 0
C16: Allada | D16: =Decade1!M15 -> 0 | E16: =Decade1!N15 -> 0 | F16: =Decade1!O15 -> 0 | G16: =Decade1!P15 -> 0 | H16: =Decade2!M13 -> 0 | I16: =Decade2!N13 -> 0 | J16: =Decade2!O13 -> 0 | K16: =Decade2!P13 -> 0 | L16: =Decade3!N14 -> 0 | M16: =Decade3!O14 -> 0 | N16: =Decade3!P14 -> 0 | O16: =Decade3!Q14 -> 0 | P16: =SUM(D16,H16,L16) -> 0 | Q16: =SUM(E16,I16,M16) -> 0 | R16: =MAX(F16,J16,N16) -> 0 | S16: =SUM(G16,K16,O16) -> 0
C17: Niaouli | D17: =Decade1!M16 -> 0 | E17: =Decade1!N16 -> 0 | F17: =Decade1!O16 -> 0 | G17: =Decade1!P16 -> 0 | H17: =Decade2!M14 -> 0 | I17: =Decade2!N14 -> 0 | J17: =Decade2!O14 -> 0 | K17: =Decade2!P14 -> 0 | L17: =Decade3!N15 -> 0 | M17: =Decade3!O15 -> 0 | N17: =Decade3!P15 -> 0 | O17: =Decade3!Q15 -> 0 | P17: =SUM(D17,H17,L17) -> 0 | Q17: =SUM(E17,I17,M17) -> 0 | R17: =MAX(F17,J17,N17) -> 0 | S17: =SUM(G17,K17,O17) -> 0
C18: Ouidah-Nord | D18: =Decade1!M17 -> 0 | E18: =Decade1!N17 -> 0 | F18: =Decade1!O17 -> 0 | G18: =Decade1!P17 -> 0 | H18: =Decade2!M15 -> 1 | I18: =Decade2!N15 -> 0 | J18: =Decade2!O15 -> 0.3 | K18: =Decade2!P15 -> 0.3 | L18: =Decade3!N16 -> 2 | M18: =Decade3!O16 -> 0 | N18: =Decade3!P16 -> 0.6 | O18: =Decade3!Q16 -> 0.9 | P18: =SUM(D18,H18,L18) -> 3 | Q18: =SUM(E18,I18,M18) -> 0 | R18: =MAX(F18,J18,N18) -> 0.6 | S18: =SUM(G18,K18,O18) -> 1.2
C19: Ouidah-Ville | D19: =Decade1!M18 -> 0 | E19: =Decade1!N18 -> 0 | F19: =Decade1!O18 -> 0 | G19: =Decade1!P18 -> 0 | H19: =Decade2!M16 -> 0 | I19: =Decade2!N16 -> 0 | J19: =Decade2!O16 -> 0 | K19: =Decade2!P16 -> 0 | L19: =Decade3!N17 -> 0 | M19: =Decade3!O17 -> 0 | N19: =Decade3!P17 -> 0 | O19: =Decade3!Q17 -> 0 | P19: =SUM(D19,H19,L19) -> 0 | Q19: =SUM(E19,I19,M19) -> 0 | R19: =MAX(F19,J19,N19) -> 0 | S19: =SUM(G19,K19,O19) -> 0
C20: Sékou | D20: =Decade1!M19 -> 0 | E20: =Decade1!N19 -> 0 | F20: =Decade1!O19 -> 0 | G20: =Decade1!P19 -> 0 | H20: =Decade2!M17 -> 0 | I20: =Decade2!N17 -> 0 | J20: =Decade2!O17 -> 0 | K20: =Decade2!P17 -> 0 | L20: =Decade3!N18 -> 0 | M20: =Decade3!O18 -> 0 | N20: =Decade3!P18 -> 0 | O20: =Decade3!Q18 -> 0 | P20: =SUM(D20,H20,L20) -> 0 | Q20: =SUM(E20,I20,M20) -> 0 | R20: =MAX(F20,J20,N20) -> 0 | S20: =SUM(G20,K20,O20) -> 0
... C22: Soava Ounmè | D22: =Decade1!M21 -> 0 | E22: =Decade1!N21 -> 0 | F22: =Decade1!O21 -> 0 | G22: =Decade1!P21 -> 0 | H22: =Decade2!M19 -> 0 | I22: =Decade2!N19 -> 0 | J22: =Decade2!O19 -> 0 | K22: =Decade2!P19 -> 0 | L22: =Decade3!N20 -> 0 | M22: =Decade3!O20 -> 0 | N22: =Decade3!P20 -> 0 | O22: =Decade3!Q20 -> 0 | P22: =SUM(D22,H22,L22) -> 0 | Q22: =SUM(E22,I22,M22) -> 0 | R22: =MAX(F22,J22,N22) -> 0 | S22: =SUM(G22,K22,O22) -> 0
B24: LEGENDE: NbJP= nombre de jours de pluie
B32: REPUBLIQUE DU BENIN
B33: MINISTERE DES TRAVAUX PUBLICS ET DES TRANSPORTS
B34: DIRECTION NATIONALE DE LA METEOROLOGIE
B35: DEPARTEMENTS | C35: LOCALITES | D35: =D5 -> CUMUL PLUVIOMETRIQUE MENSUEL: AOUT 2024
D36: 1ère décade | H36: 2ème décade | L36: 3ème décade | P36: Total
D37: NbJP | E37: NbJP > 20 mm | F37: Max | G37: Total (mm) | H37: NbJP | I37: NbJP > 20 mm | J37: Max | K37: Total (mm) | L37: NbJP | M37: NbJP > 20 mm | N37: Max | O37: Total (mm) | P37: NbJP | Q37: NbJP > 20 mm | R37: Max | S37: Total (mm)
B38: ATACORA - DONGA | C38: Birni | D38: =Decade1!M31 -> 0 | E38: =Decade1!N31 -> 0 | F38: =Decade1!O31 -> 0 | G38: =Decade1!P31 -> 0 | H38: =Decade2!M25 -> 6 | I38: =Decade2!N25 -> 3 | J38: =Decade2!O25 -> 31 | K38: =Decade2!P25 -> 104 | L38: =Decade3!N26 -> 0 | M38: =Decade3!O26 -> 0 | N38: =Decade3!P26 -> 0 | O38: =Decade3!Q26 -> 0 | P38: =SUM(D38,H38,L38) -> 6 | Q38: =SUM(E38,I38,M38) -> 3 | R38: =MAX(F38,J38,N38) -> 31 | S38: =SUM(G38,K38,O38) -> 104
C39: Boukoumbé | D39: =Decade1!M32 -> 5 | E39: =Decade1!N32 -> 3 | F39: =Decade1!O32 -> 62.8 | G39: =Decade1!P32 -> 117.3 | H39: =Decade2!M26 -> 4 | I39: =Decade2!N26 -> 2 | J39: =Decade2!O26 -> 32.8 | K39: =Decade2!P26 -> 80.5 | L39: =Decade3!N27 -> 0 | M39: =Decade3!O27 -> 0 | N39: =Decade3!P27 -> 0 | O39: =Decade3!Q27 -> 0 | P39: =SUM(D39,H39,L39) -> 9 | Q39: =SUM(E39,I39,M39) -> 5 | R39: =MAX(F39,J39,N39) -> 62.8 | S39: =SUM(G39,K39,O39) -> 197.8
C40: Dassari | D40: =Decade1!M33 -> 0 | E40: =Decade1!N33 -> 0 | F40: =Decade1!O33 -> 0 | G40: =Decade1!P33 -> 0 | H40: =Decade2!M27 -> 7 | I40: =Decade2!N27 -> 2 | J40: =Decade2!O27 -> 70.1 | K40: =Decade2!P27 -> 150.8 | L40: =Decade3!N28 -> 4 | M40: =Decade3!O28 -> 2 | N40: =Decade3!P28 -> 25.8 | O40: =Decade3!Q28 -> 72.1 | P40: =SUM(D40,H40,L40) -> 11 | Q40: =SUM(E40,I40,M40) -> 4 | R40: =MAX(F40,J40,N40) -> 70.1 | S40: =SUM(G40,K40,O40) -> 222.9
C41: Kérou | D41: =Decade1!M34 -> 7 | E41: =Decade1!N34 -> 0 | F41: =Decade1!O34 -> 19.2 | G41: =Decade1!P34 -> 79.6 | H41: =Decade2!M28 -> 5 | I41: =Decade2!N28 -> 4 | J41: =Decade2!O28 -> 57.8 | K41: =Decade2!P28 -> 166.2 | L41: =Decade3!N29 -> 6 | M41: =Decade3!O29 -> 1 | N41: =Decade3!P29 -> 41 | O41: =Decade3!Q29 -> 80.5 | P41: =SUM(D41,H41,L41) -> 18 | Q41: =SUM(E41,I41,M41) -> 5 | R41: =MAX(F41,J41,N41) -> 57.8 | S41: =SUM(G41,K41,O41) -> 326.3
C42: Kouandé | D42: =Decade1!M35 -> 0 | E42: =Decade1!N35 -> 0 | F42: =Decade1!O35 -> 0 | G42: =Decade1!P35 -> 0 | H42: =Decade2!M29 -> 6 | I42: =Decade2!N29 -> 2 | J42: =Decade2!O29 -> 65 | K42: =Decade2!P29 -> 122.7 | L42: =Decade3!N30 -> 7 | M42: =Decade3!O30 -> 2 | N42: =Decade3!P30 -> 42.2 | O42: =Decade3!Q30 -> 115.3 | P42: =SUM(D42,H42,L42) -> 13 | Q42: =SUM(E42,I42,M42) -> 4 | R42: =MAX(F42,J42,N42) -> 65 | S42: =SUM(G42,K42,O42) -> 238
C43: Matéri | D43: =Decade1!M36 -> 5 | E43: =Decade1!N36 -> 4 | F43: =Decade1!O36 -> 54.6 | G43: =Decade1!P36 -> 176 | H43: =Decade2!M30 -> 3 | I43: =Decade2!N30 -> 1 | J43: =Decade2!O30 -> 68.9 | K43: =Decade2!P30 -> 104.3 | L43: =Decade3!N31 -> 3 | M43: =Decade3!O31 -> 2 | N43: =Decade3!P31 -> 47.7 | O43: =Decade3!Q31 -> 108.4 | P43: =SUM(D43,H43,L43) -> 11 | Q43: =SUM(E43,I43,M43) -> 7 | R43: =MAX(F43,J43,N43) -> 68.9 | S43: =SUM(G43,K43,O43) -> 388.7
C44: Natitingou | D44: =Decade1!M37 -> 6 | E44: =Decade1!N37 -> 2 | F44: =Decade1!O37 -> 122 | G44: =Decade1!P37 -> 180.3 | H44: =Decade2!M31 -> 7 | I44: =Decade2!N31 -> 3 | J44: =Decade2!O31 -> 43.1 | K44: =Decade2!P31 -> 124.1 | L44: =Decade3!N32 -> 5 | M44: =Decade3!O32 -> 0 | N44: =Decade3!P32 -> 19 | O44: =Decade3!Q32 -> 66.6 | P44: =SUM(D44,H44,L44) -> 18 | Q44: =SUM(E44,I44,M44) -> 5 | R44: =MAX(F44,J44,N44) -> 122 | S44: =SUM(G44,K44,O44) -> 371
C45: Porga | D45: =Decade1!M38 -> 0 | E45: =Decade1!N38 -> 0 | F45: =Decade1!O38 -> 0 | G45: =Decade1!P38 -> 0 | H45: =Decade2!M32 -> 0 | I45: =Decade2!N32 -> 0 | J45: =Decade2!O32 -> 0 | K45: =Decade2!P32 -> 0 | L45: =Decade3!N33 -> 0 | M45: =Decade3!O33 -> 0 | N45: =Decade3!P33 -> 0 | O45: =Decade3!Q33 -> 0 | P45: =SUM(D45,H45,L45) -> 0 | Q45: =SUM(E45,I45,M45) -> 0 | R45: =MAX(F45,J45,N45) -> 0 | S45: =SUM(G45,K45,O45) -> 0
C46: Tanguieta | D46: =Decade1!M39 -> 0 | E46: =Decade1!N39 -> 0 | F46: =Decade1!O39 -> 0 | G46: =Decade1!P39 -> 0 | H46: =Decade2!M33 -> 0 | I46: =Decade2!N33 -> 0 | J46: =Decade2!O33 -> 0 | K46: =Decade2!P33 -> 0 | L46: =Decade3!N34 -> 6 | M46: =Decade3!O34 -> 0 | N46: =Decade3!P34 -> 10.3 | O46: =Decade3!Q34 -> 29 | P46: =SUM(D46,H46,L46) -> 6 | Q46: =SUM(E46,I46,M46) -> 0 | R46: =MAX(F46,J46,N46) -> 10.3 | S46: =SUM(G46,K46,O46) -> 29
C47: Péhunco | D47: =Decade1!M40 -> 5 | E47: =Decade1!N40 -> 0 | F47: =Decade1!O40 -> 19.6 | G47: =Decade1!P40 -> 50.1 | H47: =Decade2!M34 -> 3 | I47: =Decade2!N34 -> 2 | J47: =Decade2!O34 -> 90.9 | K47: =Decade2!P34 -> 125.3 | L47: =Decade3!N35 -> 0 | M47: =Decade3!O35 -> 0 | N47: =Decade3!P35 -> 0 | O47: =Decade3!Q35 -> 0 | P47: =SUM(D47,H47,L47) -> 8 | Q47: =SUM(E47,I47,M47) -> 2 | R47: =MAX(F47,J47,N47) -> 90.9 | S47: =SUM(G47,K47,O47) -> 175.4
C48: Natitingou ville | D48: =Decade1!M41 -> 0 | E48: =Decade1!N41 -> 0 | F48: =Decade1!O41 -> 0 | G48: =Decade1!P41 -> 0 | H48: =Decade2!M35 -> 0 | I48: =Decade2!N35 -> 0 | J48: =Decade2!O35 -> 0 | K48: =Decade2!P35 -> 0 | L48: =Decade3!N36 -> 5 | M48: =Decade3!O36 -> 1 | N48: =Decade3!P36 -> 20.3 | O48: =Decade3!Q36 -> 67.9 | P48: =SUM(D48,H48,L48) -> 5 | Q48: =SUM(E48,I48,M48) -> 1 | R48: =MAX(F48,J48,N48) -> 20.3 | S48: =SUM(G48,K48,O48) -> 67.9
C49: Bassila | D49: =Decade1!M42 -> 4 | E49: =Decade1!N42 -> 1 | F49: =Decade1!O42 -> 64 | G49: =Decade1!P42 -> 89.6 | H49: =Decade2!M36 -> 2 | I49: =Decade2!N36 -> 0 | J49: =Decade2!O36 -> 3.7 | K49: =Decade2!P36 -> 6.1 | L49: =Decade3!N37 -> 3 | M49: =Decade3!O37 -> 3 | N49: =Decade3!P37 -> 29.2 | O49: =Decade3!Q37 -> 82.5 | P49: =SUM(D49,H49,L49) -> 9 | Q49: =SUM(E49,I49,M49) -> 4 | R49: =MAX(F49,J49,N49) -> 64 | S49: =SUM(G49,K49,O49) -> 178.2
C50: Djougou | D50: =Decade1!M43 -> 6 | E50: =Decade1!N43 -> 2 | F50: =Decade1!O43 -> 27.4 | G50: =Decade1!P43 -> 77.5 | H50: =Decade2!M37 -> 0 | I50: =Decade2!N37 -> 0 | J50: =Decade2!O37 -> 0 | K50: =Decade2!P37 -> 0 | L50: =Decade3!N38 -> 6 | M50: =Decade3!O38 -> 2 | N50: =Decade3!P38 -> 30.7 | O50: =Decade3!Q38 -> 100.5 | P50: =SUM(D50,H50,L50) -> 12 | Q50: =SUM(E50,I50,M50) -> 4 | R50: =MAX(F50,J50,N50) -> 30.7 | S50: =SUM(G50,K50,O50) -> 178
...
